Workbook

Sheet Setup
A1: 5/3/1 FSL — Comeback Tracker (40yo · shoulder-managed)
A2: Yellow cells = edit these. Everything else auto-calculates. Units = kg. Open in Excel / LibreOffice / Google Sheets.
A4: Lift | B4: Recent weight | C4: Reps | D4: RIR (left) | E4: Est. 1RM | F4: TM % | G4: Training Max
A5: Deadlift | B5: 210 | C5: 1 | D5: 1 | E5: =B5*(1+(C5+D5)/30) | F5: 0.85 | G5: =ROUND(E5*F5/$B$10,0)*$B$10
A6: Squat | B6: 170 | C6: 5 | D6: 2 | E6: =B6*(1+(C6+D6)/30) | F6: 0.85 | G6: =ROUND(E6*F6/$B$10,0)*$B$10
A7: Bench | B7: 100 | C7: 5 | D7: 3 | E7: =B7*(1+(C7+D7)/30) | F7: 0.8 | G7: =ROUND(E7*F7/$B$10,0)*$B$10
A9: Settings
A10: Round to nearest (kg) | B10: 2.5
A12: Notes
A13: • Deadlift pre-filled from your 210 kg tough single (1 rep, ~1 RIR) → est. 1RM ≈ 220, TM ≈ 187. Edit B5:D5 if that single felt easier/harder.
A14: • Squat & Bench rows are EXAMPLES — overwrite B6:D7 with your real recent top sets (weight × reps, and reps you had left).
A15: • Est. 1RM = weight × (1 + (reps + RIR)/30) [Epley w/ reps-in-reserve].
A16: • TM % = 0.85 for squat/deadlift (standard 5/3/1). Bench = 0.80 (shoulder-conservative) — drop lower if it complains.
A17: • Increment TMs each 4-week cycle: Deadlift +5, Squat +2.5. Bench +2.5 ONLY when fully pain-free. Stall twice → reset TM to 90% and rebuild.
A18: • The whole point: top single only reaches ~80% of true 1RM. Fast bar speed > grinding. You are rebuilding tissue tolerance, not testing.

Sheet Cycle
A1: Cycle — 5/3/1 + FSL (auto-calculated from the Setup tab)
A2: Run one week per block, top-to-bottom. Week 4 = deload. '+' sets are normally AMRAP — but CAP them per the Note column.
A4: DEADLIFT | B4: Training Max (kg): | C4: ='Setup'!$G$5
A5: Week | B5: Set | C5: %TM | D5: Target reps | E5: Weight (kg) | F5: Note
A6: Wk1 (5s) | B6: 1 | C6: 0.65 | D6: 5 | E6: =ROUND('Setup'!$G$5*0.65/'Setup'!$B$10,0)*'Setup'!$B$10
B7: 2 | C7: 0.75 | D7: 5 | E7: =ROUND('Setup'!$G$5*0.75/'Setup'!$B$10,0)*'Setup'!$B$10
B8: 3 | C8: 0.85 | D8: 5+ | E8: =ROUND('Setup'!$G$5*0.85/'Setup'!$B$10,0)*'Setup'!$B$10 | F8: Top set — cap at RPE 8 (1–2 reps in reserve). No grinding, no failure.
B9: 4×5 | C9: 0.65 | D9: FSL | E9: =ROUND('Setup'!$G$5*0.65/'Setup'!$B$10,0)*'Setup'!$B$10 | F9: First-Set-Last back-off volume — same weight every set, crisp/explosive reps.
A10: Wk2 (3s) | B10: 1 | C10: 0.7 | D10: 3 | E10: =ROUND('Setup'!$G$5*0.7/'Setup'!$B$10,0)*'Setup'!$B$10
B11: 2 | C11: 0.8 | D11: 3 | E11: =ROUND('Setup'!$G$5*0.8/'Setup'!$B$10,0)*'Setup'!$B$10
B12: 3 | C12: 0.9 | D12: 3+ | E12: =ROUND('Setup'!$G$5*0.9/'Setup'!$B$10,0)*'Setup'!$B$10 | F12: Top set — cap at RPE 8 (1–2 reps in reserve). No grinding, no failure.
B13: 4×5 | C13: 0.65 | D13: FSL | E13: =ROUND('Setup'!$G$5*0.65/'Setup'!$B$10,0)*'Setup'!$B$10 | F13: First-Set-Last back-off volume — same weight every set, crisp/explosive reps.
A14: Wk3 (5/3/1) | B14: 1 | C14: 0.75 | D14: 5 | E14: =ROUND('Setup'!$G$5*0.75/'Setup'!$B$10,0)*'Setup'!$B$10
B15: 2 | C15: 0.85 | D15: 3 | E15: =ROUND('Setup'!$G$5*0.85/'Setup'!$B$10,0)*'Setup'!$B$10
B16: 3 | C16: 0.95 | D16: 1+ | E16: =ROUND('Setup'!$G$5*0.95/'Setup'!$B$10,0)*'Setup'!$B$10 | F16: Top set — cap at RPE 8 (1–2 reps in reserve). No grinding, no failure.
B17: 4×5 | C17: 0.65 | D17: FSL | E17: =ROUND('Setup'!$G$5*0.65/'Setup'!$B$10,0)*'Setup'!$B$10 | F17: First-Set-Last back-off volume — same weight every set, crisp/explosive reps.
A18: Wk4 (deload) | B18: 1 | C18: 0.4 | D18: 5 | E18: =ROUND('Setup'!$G$5*0.4/'Setup'!$B$10,0)*'Setup'!$B$10
B19: 2 | C19: 0.5 | D19: 5 | E19: =ROUND('Setup'!$G$5*0.5/'Setup'!$B$10,0)*'Setup'!$B$10
B20: 3 | C20: 0.6 | D20: 5 | E20: =ROUND('Setup'!$G$5*0.6/'Setup'!$B$10,0)*'Setup'!$B$10 | F20: Deload — easy, fast bar speed. Let tissue recover.
A22: SQUAT | B22: Training Max (kg): | C22: ='Setup'!$G$6
A23: Week | B23: Set | C23: %TM | D23: Target reps | E23: Weight (kg) | F23: Note
A24: Wk1 (5s) | B24: 1 | C24: 0.65 | D24: 5 | E24: =ROUND('Setup'!$G$6*0.65/'Setup'!$B$10,0)*'Setup'!$B$10
B25: 2 | C25: 0.75 | D25: 5 | E25: =ROUND('Setup'!$G$6*0.75/'Setup'!$B$10,0)*'Setup'!$B$10
B26: 3 | C26: 0.85 | D26: 5+ | E26: =ROUND('Setup'!$G$6*0.85/'Setup'!$B$10,0)*'Setup'!$B$10 | F26: Top set — cap at RPE 8 (1–2 reps in reserve). No grinding, no failure.
B27: 5×5 | C27: 0.65 | D27: FSL | E27: =ROUND('Setup'!$G$6*0.65/'Setup'!$B$10,0)*'Setup'!$B$10 | F27: First-Set-Last back-off volume — same weight every set, crisp/explosive reps.
A28: Wk2 (3s) | B28: 1 | C28: 0.7 | D28: 3 | E28: =ROUND('Setup'!$G$6*0.7/'Setup'!$B$10,0)*'Setup'!$B$10
B29: 2 | C29: 0.8 | D29: 3 | E29: =ROUND('Setup'!$G$6*0.8/'Setup'!$B$10,0)*'Setup'!$B$10
B30: 3 | C30: 0.9 | D30: 3+ | E30: =ROUND('Setup'!$G$6*0.9/'Setup'!$B$10,0)*'Setup'!$B$10 | F30: Top set — cap at RPE 8 (1–2 reps in reserve). No grinding, no failure.
B31: 5×5 | C31: 0.65 | D31: FSL | E31: =ROUND('Setup'!$G$6*0.65/'Setup'!$B$10,0)*'Setup'!$B$10 | F31: First-Set-Last back-off volume — same weight every set, crisp/explosive reps.
A32: Wk3 (5/3/1) | B32: 1 | C32: 0.75 | D32: 5 | E32: =ROUND('Setup'!$G$6*0.75/'Setup'!$B$10,0)*'Setup'!$B$10
B33: 2 | C33: 0.85 | D33: 3 | E33: =ROUND('Setup'!$G$6*0.85/'Setup'!$B$10,0)*'Setup'!$B$10
B34: 3 | C34: 0.95 | D34: 1+ | E34: =ROUND('Setup'!$G$6*0.95/'Setup'!$B$10,0)*'Setup'!$B$10 | F34: Top set — cap at RPE 8 (1–2 reps in reserve). No grinding, no failure.
B35: 5×5 | C35: 0.65 | D35: FSL | E35: =ROUND('Setup'!$G$6*0.65/'Setup'!$B$10,0)*'Setup'!$B$10 | F35: First-Set-Last back-off volume — same weight every set, crisp/explosive reps.
A36: Wk4 (deload) | B36: 1 | C36: 0.4 | D36: 5 | E36: =ROUND('Setup'!$G$6*0.4/'Setup'!$B$10,0)*'Setup'!$B$10
B37: 2 | C37: 0.5 | D37: 5 | E37: =ROUND('Setup'!$G$6*0.5/'Setup'!$B$10,0)*'Setup'!$B$10
B38: 3 | C38: 0.6 | D38: 5 | E38: =ROUND('Setup'!$G$6*0.6/'Setup'!$B$10,0)*'Setup'!$B$10 | F38: Deload — easy, fast bar speed. Let tissue recover.
A40: BENCH | B40: Training Max (kg): | C40: ='Setup'!$G$7
A41: Week | B41: Set | C41: %TM | D41: Target reps | E41: Weight (kg) | F41: Note
A42: Wk1 (5s) | B42: 1 | C42: 0.65 | D42: 5 | E42: =ROUND('Setup'!$G$7*0.65/'Setup'!$B$10,0)*'Setup'!$B$10
B43: 2 | C43: 0.75 | D43: 5 | E43: =ROUND('Setup'!$G$7*0.75/'Setup'!$B$10,0)*'Setup'!$B$10
...

Sheet Schedule
A1: Weekly Template & Standing Rules
A2: 5 training days + sport, but only 3–4 are truly HARD. The rest are deliberately easy. Manage hard-session density, not calendar days.
A4: Day | B4: Session | C4: Type | D4: Main work
A5: Mon | B5: Squat (hard) + push | C5: HARD | D5: Squat 5/3/1 top set @ RPE 7–8 + FSL 5×5 @ 65%. Bench 4×5 @ RPE 6–7 (reps in reserve, no AMRAP).
A6: Tue | B6: Martial arts (technical) | C6: Easy–Mod | D6: Skill / drilling emphasis, light rounds. Not the same hard muscles as Mon.
A7: Wed | B7: Bench / upper (capped) + back | C7: HARD (upper) | D7: Bench top sets @ RPE 7 + back-off + heavy rows 4×6–8. Cuff + face pulls.
A8: Thu | B8: Z2 + easy technique squat | C8: EASY | D8: Zone-2 cycle/row 30–40 min (conversational). Optional light paused squat 3×3 @ 60% for skill.
A9: Fri | B9: Deadlift (hard) + posterior chain | C9: HARD | D9: DL 5/3/1 top set @ RPE 7–8 + FSL 4×5 @ 65%. RDL / back. Post-lift loaded split work (lower body).
A10: Sat | B10: Hard sparring OR capped run | C10: HARD (sport) | D10: ONE hard sport session, ideally standalone. Not the day before/after a hard lower-body day without checking readiness.
A11: Sun | B11: Full rest + passive mobility | C11: OFF | D11: Daily passive PNF split holds only. No loading.
A13: Accessories (3–5 per hard day · RPE 7–8 · double progression)
A14: Day | B14: Movement | C14: Sets×reps | D14: Purpose
A15: Mon | B15: Leg press OR Bulgarian split squat | C15: 3×10–12 | D15: Quad volume, low spinal load; single-leg aids MA + hips
B16: Lying / seated leg curl | C16: 3×12–15 | D16: Hamstring, knee health
B17: Triceps pushdown | C17: 3×12–15 | D17: Bench lockout, elbow-friendly
B18: Hanging leg raise / ab wheel | C18: 3×10–15 | D18: Trunk / bracing
A19: Wed | B19: Chest-supported row (or seal row) | C19: 4×8–12 | D19: Back thickness, balances bench, no low-back load
B20: Neutral-grip lat pulldown | C20: 3×10–12 | D20: Vertical pull, shoulder-friendly
B21: Incline DB press, neutral grip * | C21: 3×8–12 | D21: Upper-chest / press — ONLY if pain-free
B22: DB hammer curl | C22: 3×12 | D22: Biceps / elbow health, mass
B23: Face pulls + band external rotation | C23: 3–4×15–20 | D23: Rear delt + cuff (prehab doubles as accessory)
A24: Fri | B24: Romanian deadlift | C24: 3×8–10 | D24: Ham / glute, DL carryover
B25: 45° back extension | C25: 3×12–15 | D25: Low-back / glute, low systemic cost
B26: Chest-supported / DB row | C26: 3×10 | D26: Upper back for lockout & posture
B27: Cable crunch / plank | C27: 3×10–15 / 30–45s | D27: Anti-flexion / extension core
B28: (Optional) heavy carries / grip holds | C28: 3×30m / 20–30s | D28: Grip + trunk; nods to strongman base
A29: * Defer incline press until the shoulder tolerates the full bench ladder. Double progression: hit the top of the rep range on all sets at RIR ≥ 2 → +2.5–5 kg, back to the bottom. Never to failure.
A31: Shoulder — keep running alongside (symptom-gated)
A32: Near-daily, light: band face pulls w/ end-range external rotation, serratus/wall slides, prone Y/T — 2–3 × 15–25 reps.
A33: Loaded cuff (band/cable external rotation): 3–4×/week WITH rest (not daily) — loaded beats bodyweight-only.
A34: Bench ladder, advance only when pain-free: DB floor press → DB bench → machine → pin/board press → full barbell bench.
A35: Overhead barbell = DEFERRED until full pain-free overhead flexion. Sequence: landmine → bottoms-up KB → neutral-grip DB → barbell.
A36: Pain rule: ≤5/10 during set, no rep-to-rep escalation, back to baseline next morning, no night pain. Else cut load/volume.
A37: RED FLAGS → stop & see a physio: night pain that wakes you, true weakness, numbness down the arm, the shoulder slipping. Get loading clearance.
A39: Splits / flexibility
A40: Mode A (backbone): DAILY passive/PNF on warm muscle — 2–3 × 60–120 s per position (front split each leg, side split, pancake/straddle).
A41: Mode B (complement): loaded end-range 2×/week, lower body only (weighted straddle, Cossack squats, ATG split squats, Jefferson curls).
A42: Squat/kick limiters to prioritise: ankle dorsiflexion (≥12 cm knee-to-wall), hip flexors, adductors/groin, hip external rotation (90/90).
... A48: Warning signs: FSL bar speed drops, sleep worsens, shoulder starts talking, motivation tanks. Take the deload early — don't earn it the hard way.

Sheet Log
A1: Session Log
A2: Log every hard lift. Watch bar speed & the shoulder column — they tell you when to back off before your body does.
A4: Date | B4: Day | C4: Lift | D4: Top set (wt×reps) | E4: RPE | F4: Bar speed (1–5) | G4: Shoulder pain (0–10) | H4: Sleep (h) | I4: Notes
A32: Training Max tracker (update each cycle)
A33: Cycle # | B33: Date | C33: DL TM | D33: Squat TM | E33: Bench TM | F33: Notes
